2020-05-07 00:18:39,528 DEBUG    root            Loaded Command Group: [u'gcloud', u'iam']
2020-05-07 00:18:39,531 DEBUG    root            Loaded Command Group: [u'gcloud', u'iam', u'service_accounts']
2020-05-07 00:18:39,534 DEBUG    root            Loaded Command Group: [u'gcloud', u'iam', u'service-accounts', u'create']
2020-05-07 00:18:39,537 DEBUG    root            Running [gcloud.iam.service-accounts.create] with arguments: [--project: "bot-farm-osrs", NAME: "osrs-bot-farm"]
2020-05-07 00:18:40,359 DEBUG    root            (gcloud.iam.service-accounts.create) Resource in project [bot-farm-osrs] is the subject of a conflict: Service account osrs-bot-farm already exists within project projects/bot-farm-osrs.
- '@type': type.googleapis.com/google.rpc.ResourceInfo
  resourceName: projects/bot-farm-osrs/serviceAccounts/osrs-bot-farm@bot-farm-osrs.iam.gserviceaccount.com
Traceback (most recent call last):
  File "/Users/jakevollkommer/Downloads/google-cloud-sdk/lib/googlecloudsdk/calliope/cli.py", line 983, in Execute
    resources = calliope_command.Run(cli=self, args=args)
  File "/Users/jakevollkommer/Downloads/google-cloud-sdk/lib/googlecloudsdk/calliope/backend.py", line 807, in Run
    resources = command_instance.Run(args)
  File "/Users/jakevollkommer/Downloads/google-cloud-sdk/lib/surface/iam/service_accounts/create.py", line 82, in Run
    description=args.description))))
  File "/Users/jakevollkommer/Downloads/google-cloud-sdk/lib/googlecloudsdk/third_party/apis/iam/v1/iam_v1_client.py", line 825, in Create
    config, request, global_params=global_params)
  File "/Users/jakevollkommer/Downloads/google-cloud-sdk/lib/third_party/apitools/base/py/base_api.py", line 731, in _RunMethod
    return self.ProcessHttpResponse(method_config, http_response, request)
  File "/Users/jakevollkommer/Downloads/google-cloud-sdk/lib/third_party/apitools/base/py/base_api.py", line 737, in ProcessHttpResponse
    self.__ProcessHttpResponse(method_config, http_response, request))
  File "/Users/jakevollkommer/Downloads/google-cloud-sdk/lib/third_party/apitools/base/py/base_api.py", line 604, in __ProcessHttpResponse
    http_response, method_config=method_config, request=request)
HttpConflictError: HttpError accessing <https://iam.googleapis.com/v1/projects/bot-farm-osrs/serviceAccounts?alt=json>: response: <{'status': '409', 'content-length': '392', 'x-xss-protection': '0', 'x-content-type-options': 'nosniff', 'transfer-encoding': 'chunked', 'vary': 'Origin, X-Origin, Referer', 'server': 'ESF', '-content-encoding': 'gzip', 'cache-control': 'private', 'date': 'Wed, 06 May 2020 14:18:40 GMT', 'x-frame-options': 'SAMEORIGIN', 'alt-svc': 'h3-Q050=":443"; ma=2592000,h3-Q049=":443"; ma=2592000,h3-Q048=":443"; ma=2592000,h3-Q046=":443"; ma=2592000,h3-Q043=":443"; ma=2592000,quic=":443"; ma=2592000; v="46,43"', 'content-type': 'application/json; charset=UTF-8'}>, content <{
  "error": {
    "code": 409,
    "message": "Service account osrs-bot-farm already exists within project projects/bot-farm-osrs.",
    "status": "ALREADY_EXISTS",
    "details": [
      {
        "@type": "type.googleapis.com/google.rpc.ResourceInfo",
        "resourceName": "projects/bot-farm-osrs/serviceAccounts/osrs-bot-farm@bot-farm-osrs.iam.gserviceaccount.com"
      }
    ]
  }
}
>
2020-05-07 00:18:40,364 ERROR    root            (gcloud.iam.service-accounts.create) Resource in project [bot-farm-osrs] is the subject of a conflict: Service account osrs-bot-farm already exists within project projects/bot-farm-osrs.
- '@type': type.googleapis.com/google.rpc.ResourceInfo
  resourceName: projects/bot-farm-osrs/serviceAccounts/osrs-bot-farm@bot-farm-osrs.iam.gserviceaccount.com
2020-05-07 00:18:40,389 DEBUG    root            Metrics reporting process started...
